nohup: 忽略输入
[I 2024-09-15 09:27:31.463 ServerApp] Package jupyterlab took 0.0000s to import
[I 2024-09-15 09:27:31.469 ServerApp] Package jupyter_lsp took 0.0062s to import
[W 2024-09-15 09:27:31.469 ServerApp] A `_jupyter_server_extension_points` function was not found in jupyter_lsp. Instead, a `_jupyter_server_extension_paths` function was found and will be used for now. This function name will be deprecated in future releases of Jupyter Server.
[I 2024-09-15 09:27:31.472 ServerApp] Package jupyter_server_terminals took 0.0033s to import
[I 2024-09-15 09:27:31.473 ServerApp] Package notebook_shim took 0.0000s to import
[W 2024-09-15 09:27:31.473 ServerApp] A `_jupyter_server_extension_points` function was not found in notebook_shim. Instead, a `_jupyter_server_extension_paths` function was found and will be used for now. This function name will be deprecated in future releases of Jupyter Server.
[I 2024-09-15 09:27:31.473 ServerApp] jupyter_lsp | extension was successfully linked.
[I 2024-09-15 09:27:31.474 ServerApp] jupyter_server_terminals | extension was successfully linked.
[I 2024-09-15 09:27:31.476 ServerApp] jupyterlab | extension was successfully linked.
[I 2024-09-15 09:27:31.598 ServerApp] notebook_shim | extension was successfully linked.
[I 2024-09-15 09:27:31.620 ServerApp] notebook_shim | extension was successfully loaded.
[I 2024-09-15 09:27:31.621 ServerApp] jupyter_lsp | extension was successfully loaded.
[I 2024-09-15 09:27:31.622 ServerApp] jupyter_server_terminals | extension was successfully loaded.
[I 2024-09-15 09:27:31.623 LabApp] JupyterLab extension loaded from /home/liuyq/anaconda3/envs/dl/lib/python3.10/site-packages/jupyterlab
[I 2024-09-15 09:27:31.623 LabApp] JupyterLab application directory is /home/liuyq/anaconda3/envs/dl/share/jupyter/lab
[I 2024-09-15 09:27:31.624 LabApp] Extension Manager is 'pypi'.
[I 2024-09-15 09:27:31.625 ServerApp] jupyterlab | extension was successfully loaded.
[I 2024-09-15 09:27:31.625 ServerApp] Serving notebooks from local directory: /mnt/sda/liuyq/asso_rule2
[I 2024-09-15 09:27:31.626 ServerApp] Jupyter Server 2.7.0 is running at:
[I 2024-09-15 09:27:31.626 ServerApp] http://ps:8701/lab
[I 2024-09-15 09:27:31.626 ServerApp]     http://127.0.0.1:8701/lab
[I 2024-09-15 09:27:31.626 ServerApp] Use Control-C to stop this server and shut down all kernels (twice to skip confirmation).
[I 2024-09-15 09:27:31.725 ServerApp] Skipped non-installed server(s): bash-language-server, dockerfile-language-server-nodejs, javascript-typescript-langserver, jedi-language-server, julia-language-server, pyright, python-language-server, python-lsp-server, r-languageserver, sql-language-server, texlab, typescript-language-server, unified-language-server, vscode-css-languageserver-bin, vscode-html-languageserver-bin, vscode-json-languageserver-bin, yaml-language-server
[W 2024-09-15 09:27:51.797 ServerApp] wrote error: 'Forbidden'
    Traceback (most recent call last):
      File "/home/liuyq/anaconda3/envs/dl/lib/python3.10/site-packages/tornado/web.py", line 1711, in _execute
        result = method(*self.path_args, **self.path_kwargs)
      File "/home/liuyq/anaconda3/envs/dl/lib/python3.10/site-packages/tornado/web.py", line 3196, in wrapper
        url = self.get_login_url()
      File "/home/liuyq/anaconda3/envs/dl/lib/python3.10/site-packages/jupyter_server/base/handlers.py", line 753, in get_login_url
        raise web.HTTPError(403)
    tornado.web.HTTPError: HTTP 403: Forbidden
[W 2024-09-15 09:27:51.807 ServerApp] 403 GET /api/sessions (@10.213.98.197) 10.26ms referer=None
[I 2024-09-15 09:27:51.949 ServerApp] User 5c6b3f12172e4c6b8b1f68c718887266 logged in.
[I 2024-09-15 09:27:51.949 ServerApp] 302 POST /login (5c6b3f12172e4c6b8b1f68c718887266@10.213.98.197) 16.83ms
[I 2024-09-15 09:27:51.951 ServerApp] 302 GET / (@10.213.98.197) 0.13ms
[I 2024-09-15 09:30:01.399 ServerApp] 302 GET / (@172.25.66.255) 0.17ms
[I 2024-09-15 09:30:01.409 LabApp] 302 GET /lab? (@172.25.66.255) 0.22ms
[W 2024-09-15 09:30:07.839 ServerApp] 401 POST /login?next=%2Flab%3F (@172.25.66.255) 13.69ms referer=http://172.24.141.222:8701/login?next=%2Flab%3F
[I 2024-09-15 09:30:15.596 ServerApp] User 1845158ae87c4da7a8efe1074fa5f77b logged in.
[I 2024-09-15 09:30:15.596 ServerApp] 302 POST /login?next=%2Flab%3F (1845158ae87c4da7a8efe1074fa5f77b@172.25.66.255) 17.00ms
Unable to load extension: pydevd_plugins.extensions.types.pydevd_plugin_pandas_types
[W 2024-09-15 09:30:20.284 LabApp] Could not determine jupyterlab build status without nodejs
[W 2024-09-15 09:30:20.621 ServerApp] 404 GET /api/contents/test/tutorial-Copy1.ipynb?content=0&1726363818711 (172.25.66.255): No such file or directory: test/tutorial-Copy1.ipynb
[W 2024-09-15 09:30:20.621 ServerApp] wrote error: 'No such file or directory: test/tutorial-Copy1.ipynb'
    Traceback (most recent call last):
      File "/home/liuyq/anaconda3/envs/dl/lib/python3.10/site-packages/tornado/web.py", line 1713, in _execute
        result = await result
      File "/home/liuyq/anaconda3/envs/dl/lib/python3.10/site-packages/jupyter_server/services/contents/handlers.py", line 121, in get
        model = await ensure_async(
      File "/home/liuyq/anaconda3/envs/dl/lib/python3.10/site-packages/jupyter_core/utils/__init__.py", line 182, in ensure_async
        result = await obj
      File "/home/liuyq/anaconda3/envs/dl/lib/python3.10/site-packages/jupyter_server/services/contents/filemanager.py", line 877, in get
        raise web.HTTPError(404, "No such file or directory: %s" % path)
    tornado.web.HTTPError: HTTP 404: Not Found (No such file or directory: test/tutorial-Copy1.ipynb)
[W 2024-09-15 09:30:20.621 ServerApp] 404 GET /api/contents/test/tutorial-Copy1.ipynb?content=0&1726363818711 (1845158ae87c4da7a8efe1074fa5f77b@172.25.66.255) 0.87ms referer=http://172.24.141.222:8701/lab?
[W 2024-09-15 09:30:20.622 ServerApp] 404 GET /api/contents/test/tutorial.ipynb?content=0&1726363818710 (172.25.66.255): No such file or directory: test/tutorial.ipynb
[W 2024-09-15 09:30:20.622 ServerApp] wrote error: 'No such file or directory: test/tutorial.ipynb'
    Traceback (most recent call last):
      File "/home/liuyq/anaconda3/envs/dl/lib/python3.10/site-packages/tornado/web.py", line 1713, in _execute
        result = await result
      File "/home/liuyq/anaconda3/envs/dl/lib/python3.10/site-packages/jupyter_server/services/contents/handlers.py", line 121, in get
        model = await ensure_async(
      File "/home/liuyq/anaconda3/envs/dl/lib/python3.10/site-packages/jupyter_core/utils/__init__.py", line 182, in ensure_async
        result = await obj
      File "/home/liuyq/anaconda3/envs/dl/lib/python3.10/site-packages/jupyter_server/services/contents/filemanager.py", line 877, in get
        raise web.HTTPError(404, "No such file or directory: %s" % path)
    tornado.web.HTTPError: HTTP 404: Not Found (No such file or directory: test/tutorial.ipynb)
[W 2024-09-15 09:30:20.622 ServerApp] 404 GET /api/contents/test/tutorial.ipynb?content=0&1726363818710 (1845158ae87c4da7a8efe1074fa5f77b@172.25.66.255) 0.33ms referer=http://172.24.141.222:8701/lab?
[W 2024-09-15 09:30:20.626 ServerApp] 404 GET /api/contents/reproducibility/Fig4.ipynb?content=0&1726363818711 (172.25.66.255): No such file or directory: reproducibility/Fig4.ipynb
[W 2024-09-15 09:30:20.626 ServerApp] wrote error: 'No such file or directory: reproducibility/Fig4.ipynb'
    Traceback (most recent call last):
      File "/home/liuyq/anaconda3/envs/dl/lib/python3.10/site-packages/tornado/web.py", line 1713, in _execute
        result = await result
      File "/home/liuyq/anaconda3/envs/dl/lib/python3.10/site-packages/jupyter_server/services/contents/handlers.py", line 121, in get
        model = await ensure_async(
      File "/home/liuyq/anaconda3/envs/dl/lib/python3.10/site-packages/jupyter_core/utils/__init__.py", line 182, in ensure_async
        result = await obj
      File "/home/liuyq/anaconda3/envs/dl/lib/python3.10/site-packages/jupyter_server/services/contents/filemanager.py", line 877, in get
        raise web.HTTPError(404, "No such file or directory: %s" % path)
    tornado.web.HTTPError: HTTP 404: Not Found (No such file or directory: reproducibility/Fig4.ipynb)
[W 2024-09-15 09:30:20.626 ServerApp] 404 GET /api/contents/reproducibility/Fig4.ipynb?content=0&1726363818711 (1845158ae87c4da7a8efe1074fa5f77b@172.25.66.255) 0.48ms referer=http://172.24.141.222:8701/lab?
[I 2024-09-15 09:30:20.653 ServerApp] New terminal with automatic name: 3
[I 2024-09-15 09:30:20.657 ServerApp] New terminal with automatic name: 1
[W 2024-09-15 09:30:21.387 ServerApp] 404 GET /api/contents/reproducibility?1726363819483 (172.25.66.255): No such file or directory: reproducibility
[W 2024-09-15 09:30:21.387 ServerApp] wrote error: 'No such file or directory: reproducibility'
    Traceback (most recent call last):
      File "/home/liuyq/anaconda3/envs/dl/lib/python3.10/site-packages/tornado/web.py", line 1713, in _execute
        result = await result
      File "/home/liuyq/anaconda3/envs/dl/lib/python3.10/site-packages/jupyter_server/services/contents/handlers.py", line 121, in get
        model = await ensure_async(
      File "/home/liuyq/anaconda3/envs/dl/lib/python3.10/site-packages/jupyter_core/utils/__init__.py", line 182, in ensure_async
        result = await obj
      File "/home/liuyq/anaconda3/envs/dl/lib/python3.10/site-packages/jupyter_server/services/contents/filemanager.py", line 877, in get
        raise web.HTTPError(404, "No such file or directory: %s" % path)
    tornado.web.HTTPError: HTTP 404: Not Found (No such file or directory: reproducibility)
[W 2024-09-15 09:30:21.388 ServerApp] 404 GET /api/contents/reproducibility?1726363819483 (1845158ae87c4da7a8efe1074fa5f77b@172.25.66.255) 0.39ms referer=http://172.24.141.222:8701/lab?
[I 2024-09-15 09:32:40.008 ServerApp] 302 GET /api/kernelspecs/ (@10.213.98.197) 0.15ms
[W 2024-09-15 09:32:40.010 ServerApp] wrote error: 'Forbidden'
    Traceback (most recent call last):
      File "/home/liuyq/anaconda3/envs/dl/lib/python3.10/site-packages/tornado/web.py", line 1711, in _execute
        result = method(*self.path_args, **self.path_kwargs)
      File "/home/liuyq/anaconda3/envs/dl/lib/python3.10/site-packages/tornado/web.py", line 3196, in wrapper
        url = self.get_login_url()
      File "/home/liuyq/anaconda3/envs/dl/lib/python3.10/site-packages/jupyter_server/base/handlers.py", line 753, in get_login_url
        raise web.HTTPError(403)
    tornado.web.HTTPError: HTTP 403: Forbidden
[W 2024-09-15 09:32:40.010 ServerApp] 403 GET /api/kernelspecs (@10.213.98.197) 0.31ms referer=None
[I 2024-09-15 09:32:40.034 ServerApp] User 277615d821124eb6a817c009d371e197 logged in.
[I 2024-09-15 09:32:40.035 ServerApp] 302 POST /login (277615d821124eb6a817c009d371e197@10.213.98.197) 13.27ms
[I 2024-09-15 09:32:40.037 ServerApp] 302 GET / (@10.213.98.197) 0.14ms
[I 2024-09-15 09:32:40.051 ServerApp] 302 GET /api/kernelspecs/ (@10.213.98.197) 0.10ms
[I 2024-09-15 09:32:40.098 ServerApp] Kernel started: e43fa4f0-1c03-483e-a324-66f6a4364318
[W 2024-09-15 09:32:40.240 ServerApp] No session ID specified
Unable to load extension: pydevd_plugins.extensions.types.pydevd_plugin_pandas_types
[I 2024-09-15 09:32:40.429 ServerApp] Connecting to kernel e43fa4f0-1c03-483e-a324-66f6a4364318.
2024-09-15 09:32:44.092729: I tensorflow/core/util/port.cc:110] oneDNN custom operations are on. You may see slightly different numerical results due to floating-point round-off errors from different computation orders. To turn them off, set the environment variable `TF_ENABLE_ONEDNN_OPTS=0`.
2024-09-15 09:32:44.266692: I tensorflow/core/platform/cpu_feature_guard.cc:182] This TensorFlow binary is optimized to use available CPU instructions in performance-critical operations.
To enable the following instructions: AVX2 AVX_VNNI FMA, in other operations, rebuild TensorFlow with the appropriate compiler flags.
2024-09-15 09:32:44.743044: W tensorflow/compiler/tf2tensorrt/utils/py_utils.cc:38] TF-TRT Warning: Could not find TensorRT
[I 2024-09-15 13:07:04.727 ServerApp] 302 GET /api/kernelspecs/ (@10.213.98.197) 0.18ms
[I 2024-09-15 13:07:04.731 ServerApp] 302 GET /api/kernelspecs/ (@10.213.98.197) 0.09ms
[I 2024-09-15 13:07:04.749 ServerApp] Kernel started: ea7538ce-9708-4bdf-8136-182f58e8954d
[W 2024-09-15 13:07:04.756 ServerApp] No session ID specified
Unable to load extension: pydevd_plugins.extensions.types.pydevd_plugin_pandas_types
[I 2024-09-15 13:07:05.037 ServerApp] Connecting to kernel ea7538ce-9708-4bdf-8136-182f58e8954d.
2024-09-15 13:07:05.134551: I tensorflow/core/util/port.cc:110] oneDNN custom operations are on. You may see slightly different numerical results due to floating-point round-off errors from different computation orders. To turn them off, set the environment variable `TF_ENABLE_ONEDNN_OPTS=0`.
2024-09-15 13:07:05.157625: I tensorflow/core/platform/cpu_feature_guard.cc:182] This TensorFlow binary is optimized to use available CPU instructions in performance-critical operations.
To enable the following instructions: AVX2 AVX_VNNI FMA, in other operations, rebuild TensorFlow with the appropriate compiler flags.
2024-09-15 13:07:05.507755: W tensorflow/compiler/tf2tensorrt/utils/py_utils.cc:38] TF-TRT Warning: Could not find TensorRT
[I 2024-09-15 13:08:16.076 ServerApp] 302 GET /api/kernelspecs/ (@10.213.98.197) 0.18ms
[I 2024-09-15 13:08:16.082 ServerApp] 302 GET /api/kernelspecs/ (@10.213.98.197) 0.09ms
[I 2024-09-15 13:08:16.098 ServerApp] Kernel started: ed76f6ca-d1c3-40cf-83fa-e3cec5c522a2
[W 2024-09-15 13:08:16.106 ServerApp] No session ID specified
Unable to load extension: pydevd_plugins.extensions.types.pydevd_plugin_pandas_types
[I 2024-09-15 13:08:16.335 ServerApp] Connecting to kernel ed76f6ca-d1c3-40cf-83fa-e3cec5c522a2.
